Workbook

Sheet Crime Stats Per Suburb
A1: Suburb | B1: Total Crimes Per Population 2025 | C1: High Risk Alcohol Consumption | D1: Education Levels Year 9 and Below | E1: Proportion Low Income Households | F1: Non Workforce Participation
A2: Blacktown | B2: =12912/Education!F3 -> 0.032542291 | C2: ='Alcohol Consumption'!B2 -> 0.085 | D2: =Education!G3 -> 0.083195556 | E2: =Poverty!B2 -> 0.125 | F2: =Unemployment!E2 -> 0.337
A3: Sydney CBD | B3: =8742/Education!F2 -> 0.55770335 | C3: ='Alcohol Consumption'!B3 -> 0.18 | D3: =Education!G2 -> 0.036299841 | E3: =Poverty!B3 -> 0.1702815 | F3: =Unemployment!E3 -> 0.25
A4: Penrith | B4: =8328/Education!F4 -> 0.038260806 | C4: ='Alcohol Consumption'!B4 -> 0.09 | D4: =Education!G4 -> 0.090350265 | E4: =Poverty!B4 -> 0.135 | F4: =Unemployment!E4 -> 0.317
A5: Mount Druitt | B5: =10654/Education!F5 -> 0.62722242 | C5: ='Alcohol Consumption'!B5 -> 0.085 | D5: =Education!G5 -> 0.069704462 | E5: =Poverty!B5 -> 0.166 | F5: =Unemployment!E5 -> 0.416
A6: Campbelltown | B6: =7913/Education!F6 -> 0.044828036 | C6: ='Alcohol Consumption'!B6 -> 0.09 | D6: =Education!G6 -> 0.092607595 | E6: =Poverty!B6 -> 0.19451055 | F6: =Unemployment!E6 -> 0.373
A7: Liverpool | B7: =15069/Education!F7 -> 0.06455026 | C7: ='Alcohol Consumption'!B7 -> 0.085 | D7: =Education!G7 -> 0.11039384 | E7: =Poverty!B7 -> 0.151 | F7: =Unemployment!E7 -> 0.404
A8: Paramatta | B8: =10116/Education!F8 -> 0.039403418 | C8: ='Alcohol Consumption'!B8 -> 0.07 | D8: =Education!G8 -> 0.063272945 | E8: =Poverty!B8 -> 0.131 | F8: =Unemployment!E8 -> 0.33
A9: St Marys | B9: =7356/Education!F9 -> 0.55491853 | C9: ='Alcohol Consumption'!B9 -> 0.09 | D9: =Education!G9 -> 0.098521424 | E9: =Poverty!B9 -> 0.18235171 | F9: =Unemployment!E9 -> 0.353
A10: Surry Hills | B10: =5188/Education!F10 -> 0.32777357 | C10: ='Alcohol Consumption'!B10 -> 0.18 | D10: =Education!G10 -> 0.026408896 | E10: =Poverty!B10 -> 0.13760288 | F10: =Unemployment!E10 -> 0.212
A11: Melbourne CBD | B11: =18024/Education!F11 -> 0.32806101 | C11: ='Alcohol Consumption'!B11 -> 0.135 | D11: =Education!G11 -> 0.031379116 | E11: =Poverty!B15 -> 0.18 | F11: =Unemployment!E16 -> 0.218
A12: Yarra | B12: =4111/Education!F12 -> 1.429913 | C12: ='Alcohol Consumption'!B12 -> 0.22 | D12: =Education!G12 -> 0.10991304 | E12: =Poverty!B16 -> 0.132 | F12: =Unemployment!E17 -> 0.38
A13: Carlton | B13: =2694/Education!F13 -> 0.16779819 | C13: ='Alcohol Consumption'!B13 -> 0.22 | D13: =Education!G13 -> 0.041046403 | E13: =Poverty!B17 -> 0.297 | F13: =Unemployment!E18 -> 0.306
A14: Frankston | B14: =9307/Education!F14 -> 0.24931022 | C14: ='Alcohol Consumption'!B14 -> 0.108 | D14: =Education!G14 -> 0.085183895 | E14: =Poverty!B18 -> 0.22 | F14: =Unemployment!E19 -> 0.337
A15: Campbellfield | B15: =8169/Education!F15 -> 1.6413502 | C15: ='Alcohol Consumption'!B15 -> 0.076 | D15: =Education!G15 -> 0.21719912 | E15: =Poverty!B19 -> 0.248 | F15: =Unemployment!E20 -> 0.508
A16: Docklands | B16: =3037/Education!F16 -> 0.19599871 | C16: ='Alcohol Consumption'!B16 -> 0.135 | D16: =Education!G16 -> 0.032462085 | E16: =Poverty!B20 -> 0.139 | F16: =Unemployment!E21 -> 0.199
A17: Southbank | B17: =3322/Education!F17 -> 0.1467898 | C17: ='Alcohol Consumption'!B17 -> 0.135 | D17: =Education!G17 -> 0.028765852 | E17: =Poverty!B21 -> 0.119 | F17: =Unemployment!E22 -> 0.166
A18: Broadmeadows | B18: =3932/Education!F18 -> 0.3139572 | C18: ='Alcohol Consumption'!B18 -> 0.076 | D18: =Education!G18 -> 0.15993293 | E18: =Poverty!B22 -> 0.255 | F18: =Unemployment!E23 -> 0.451
A19: St Kilda | B19: =4364/Education!F19 -> 0.2239097 | C19: ='Alcohol Consumption'!B19 -> 0.206 | D19: =Education!G19 -> 0.041303232 | E19: =Poverty!B23 -> 0.141 | F19: =Unemployment!E24 -> 0.191
A20: Melton | B20: =16827/Education!F20 -> 2.1158054 | C20: ='Alcohol Consumption'!B20 -> 0.09 | D20: =Education!G20 -> 0.13428895 | E20: =Poverty!B24 -> 0.266 | F20: =Unemployment!E25 -> 0.444
A21: Werribe | B21: =5644/Education!F21 -> 0.11281908 | C21: ='Alcohol Consumption'!B21 -> 0.096 | D21: =Education!G21 -> 0.10658245 | E21: =Poverty!B25 -> 0.161 | F21: =Unemployment!E26 -> 0.318
A22: Morwell | B22: =14011/Education!F22 -> 0.97372993 | C22: ='Alcohol Consumption'!B22 -> 0.076 | D22: =Education!G22 -> 0.13955105 | E22: =Poverty!B26 -> 0.323 | F22: =Unemployment!E27 -> 0.449
A23: Civic | B23: =1120/Education!F23 -> 0.23164426 | C23: ='Alcohol Consumption'!B23 -> 0.268 | D23: =Education!G23 -> 0.016339193 | E23: =Poverty!B27 -> 0.119 | F23: =Unemployment!E28 -> 0.212
A24: Belconnen | B24: =980/Education!F24 -> 0.115267 | C24: ='Alcohol Consumption'!B24 -> 0.185 | D24: =Education!G24 -> 0.034697718 | E24: =Poverty!B28 -> 0.105 | F24: =Unemployment!E29 -> 0.219
A25: Kambah | B25: =620/Education!F24 -> 0.072924018 | C25: ='Alcohol Consumption'!B25 -> 0.185 | D25: =Education!G25 -> 0.070325463 | E25: =Poverty!B29 -> 0.1 | F25: =Unemployment!E30 -> 0.335
A26: Phillip | B26: =550/Education!F26 -> 0.10583029 | C26: ='Alcohol Consumption'!B26 -> 0.268 | D26: =Education!G26 -> 0.031556667 | E26: =Poverty!B30 -> 0.076 | F26: =Unemployment!E31 -> 0.159
A27: Gungahlin | B27: =710/Education!F27 -> 0.082692756 | C27: ='Alcohol Consumption'!B27 -> 0.185 | D27: =Education!G27 -> 0.054157932 | E27: =Poverty!B31 -> 0.091 | F27: =Unemployment!E32 -> 0.202
A28: Braddon | B28: =580/Education!F28 -> 0.090866364 | C28: ='Alcohol Consumption'!B28 -> 0.37 | D28: =Education!G28 -> 0.027573241 | E28: =Poverty!B32 -> 0.119 | F28: =Unemployment!E33 -> 0.142
A29: Ngunnawal | B29: =350/Education!F29 -> 0.03194305 | C29: ='Alcohol Consumption'!B29 -> 0.185 | D29: =Education!G29 -> 0.058957744 | E29: =Poverty!B33 -> 0.09 | F29: =Unemployment!E34 -> 0.24
A30: Richardson | B30: =380/Education!F30 -> 0.12426422 | C30: ='Alcohol Consumption'!B30 -> 0.185 | D30: =Education!G30 -> 0.080444735 | E30: =Poverty!B34 -> 0.101 | F30: =Unemployment!E35 -> 0.277
A31: Charnwood | B31: =450/Education!F31 -> 0.14729951 | C31: ='Alcohol Consumption'!B31 -> 0.31 | D31: =Education!G31 -> 0.08314239 | E31: =Poverty!B35 -> 0.12 | F31: =Unemployment!E36 -> 0.297
A32: Narrabundah | B32: =320/Education!F32 -> 0.049573974 | C32: ='Alcohol Consumption'!B32 -> 0.37 | D32: =Education!G32 -> 0.055460883 | E32: =Poverty!B36 -> 0.075 | F32: =Unemployment!E37 -> 0.3
A33: Adelaide CBD | B33: =8510/Education!F33 -> 0.46753104 | C33: ='Alcohol Consumption'!B33 -> 0.32 | D33: =Education!G33 -> 0.040544995 | E33: =Poverty!B37 -> 0.275 | F33: =Unemployment!E38 -> 0.336
A34: Sailsbury | B34: =1980/Education!F34 -> 0.22395657 | C34: ='Alcohol Consumption'!B34 -> 0.22 | D34: =Education!G34 -> 0.16774121 | E34: =Poverty!B38 -> 0.23 | F34: =Unemployment!E39 -> 0.446
A35: Elizabeth | B35: =1530/Education!F35 -> 1.4811229 | C35: ='Alcohol Consumption'!B35 -> 0.26 | D35: =Education!G35 -> 0.11907067 | E35: =Poverty!B39 -> 0.275 | F35: =Unemployment!E40 -> 0.469
A36: Daveron Park | B36: =1210/Education!F36 -> 0.18929912 | C36: ='Alcohol Consumption'!B36 -> 0.25 | D36: =Education!G36 -> 0.13548185 | E36: =Poverty!B40 -> 0.29 | F36: =Unemployment!E41 -> 0.467
A37: Oaklands Park | B37: =1150/Education!F37 -> 0.29128673 | C37: ='Alcohol Consumption'!B37 -> 0.19 | D37: =Education!G37 -> 0.089665653 | E37: =Poverty!B41 -> 0.26 | F37: =Unemployment!E42 -> 0.4
A38: Paralowie | B38: =890/Education!F38 -> 0.050845521 | C38: ='Alcohol Consumption'!B38 -> 0.2 | D38: =Education!G38 -> 0.12048675 | E38: =Poverty!B42 -> 0.2 | F38: =Unemployment!E43 -> 0.332
A39: Ingle Farm | B39: =770/Education!F39 -> 0.080687415 | C39: ='Alcohol Consumption'!B39 -> 0.21 | D39: =Education!G39 -> 0.10719899 | E39: =Poverty!B43 -> 0.21 | F39: =Unemployment!E44 -> 0.39
A40: Glenelg | B40: =727/Education!F40 -> 0.21133721 | C40: ='Alcohol Consumption'!B40 -> 0.34 | D40: =Education!G40 -> 0.068604651 | E40: =Poverty!B44 -> 0.11 | F40: =Unemployment!E45 -> 0.435
...

Sheet Education
A1: Suburb | B1: Year 9 or below | C1: Inadequately Described | D1: No Educational Attainment | E1: Total | F1: Population | G1: Percentage
A2: Sydney CBD | B2: 159 | C2: 188 | D2: 222 | E2: =SUM(B2:D2) -> 569 | F2: 15675 | G2: =E2/F2 -> 0.036299841
A3: Blacktown | B3: 21688 | C3: 7891 | D3: 3431 | E3: =SUM(B3:D3) -> 33010 | F3: 396776 | G3: =E3/F3 -> 0.083195556
A4: Penrith | B4: 14025 | C4: 4513 | D4: 1128 | E4: =SUM(B4:D4) -> 19666 | F4: 217664 | G4: =E4/F4 -> 0.090350265
A5: Mount Druitt | B5: 8 | C5: 0 | D5: 1176 | E5: =SUM(B5:D5) -> 1184 | F5: 16986 | G5: =E5/F5 -> 0.069704462
A6: Campbelltown | B6: 11172 | C6: 3787 | D6: 1388 | E6: =SUM(B6:D6) -> 16347 | F6: 176519 | G6: =E6/F6 -> 0.092607595
A7: Liverpool | B7: 15802 | C7: 4746 | D7: 5223 | E7: =SUM(B7:D7) -> 25771 | F7: 233446 | G7: =E7/F7 -> 0.11039384
A8: Paramatta | B8: 8866 | C8: 5592 | D8: 1786 | E8: =SUM(B8:D8) -> 16244 | F8: 256729 | G8: =E8/F8 -> 0.063272945
A9: St Marys | B9: 966 | C9: 234 | D9: 106 | E9: =SUM(B9:D9) -> 1306 | F9: 13256 | G9: =E9/F9 -> 0.098521424
A10: Surry Hills | B10: 33 | C10: 308 | D10: 77 | E10: =SUM(B10:D10) -> 418 | F10: 15828 | G10: =E10/F10 -> 0.026408896
A11: Melbourne CBD | B11: 597 | C11: 925 | D11: 202 | E11: =SUM(B11:D11) -> 1724 | F11: 54941 | G11: =E11/F11 -> 0.031379116
A12: Yarra | B12: 262 | C12: 44 | D12: 10 | E12: =SUM(B12:D12) -> 316 | F12: 2875 | G12: =E12/F12 -> 0.10991304
A13: Carlton | B13: 297 | C13: 243 | D13: 119 | E13: =SUM(B13:D13) -> 659 | F13: 16055 | G13: =E13/F13 -> 0.041046403
... A82: Nightcliff | B82: 117 | C82: 60 | D82: 20 | E82: =SUM(B82:D82) -> 197 | F82: 3884 | G82: =E82/F82 -> 0.050720906

Sheet Alcohol Consumption
A1: Suburb | B1: Percentage Very High Risk Drinking (in LGA or LHD)
A2: Blacktown | B2: 0.085
A3: Sydney CBD | B3: 0.18
A4: Penrith | B4: 0.09 | D4: This measures the proportion of the population that drinks at highly risky amounts over the daily maximum safe alcohol consumption level, at least oncea week.
A5: Mount Druitt | B5: 0.085
A6: Campbelltown | B6: 0.09
A7: Liverpool | B7: 0.085
A8: Paramatta | B8: 0.07
A9: St Marys | B9: 0.09
A10: Surry Hills | B10: 0.18
A11: Melbourne CBD | B11: 0.135
A12: Yarra | B12: 0.22 | D12: Weekly Recommended Alcohol Consumption | E12: 10
A13: Carlton | B13: 0.22 | D13: Daily maximum safe alcohol consumption | E13: 4
A14: Frankston | B14: 0.108
A15: Campbellfield | B15: 0.076
A16: Docklands | B16: 0.135
A17: Southbank | B17: 0.135
A18: Broadmeadows | B18: 0.076
A19: St Kilda | B19: 0.206
A20: Melton | B20: 0.09
A21: Werribe | B21: 0.096
A22: Morwell | B22: 0.076
A23: Civic | B23: 0.268
A24: Belconnen | B24: 0.185
A25: Kambah | B25: 0.185
... A82: Nightcliff | B82: 0.39

Sheet Unemployment
A1: Suburb | B1: Proportion Not In Labour Force | C1: Proportion who refused to state if they were in labour force | D1: Total | E1: Total Disparity In Labour Force
A2: Blacktown | B2: =33.7% -> 0.337 | D2: =C2+B2 -> 0.337 | E2: =D2 -> 0.337
A3: Sydney CBD and South | B3: 0.25 | D3: =C3+B3 -> 0.25 | E3: =D3 -> 0.25
A4: Penrith | B4: 0.317 | D4: =C4+B4 -> 0.317 | E4: =D4 -> 0.317
A5: Mount Druitt | B5: 0.416 | D5: =C5+B5 -> 0.416 | E5: =D5 -> 0.416
A6: Campbelltown | B6: 0.373 | D6: =C6+B6 -> 0.373 | E6: =D6 -> 0.373
A7: Liverpool | B7: 0.404 | D7: =C7+B7 -> 0.404 | E7: =D7 -> 0.404
A8: Paramatta | B8: 0.33 | D8: =C8+B8 -> 0.33 | E8: =D8 -> 0.33
A9: St Marys | B9: 0.353 | D9: =C9+B9 -> 0.353 | E9: =D9 -> 0.353
A10: Surry Hills | B10: 0.212 | D10: =C10+B10 -> 0.212 | E10: =D10 -> 0.212
A12: National Proportion Outside Labour Force | B12: =0.331 -> 0.331
A13: National Proportion Refused to state if they were in labour force | B13: 0 | C13: =0.058 -> 0.058
A14: National Total
A16: Melbourne CBD | B16: 0.218 | D16: =SUM(B16:C16) -> 0.218 | E16: =D16-B14 -> 0.218
A17: Yarra | B17: 0.38 | D17: =SUM(B17:C17) -> 0.38 | E17: =D17-B14 -> 0.38
A18: Carlton | B18: 0.306 | D18: =SUM(B18:C18) -> 0.306 | E18: =D18-B14 -> 0.306
A19: Frankston | B19: 0.337 | D19: =SUM(B19:C19) -> 0.337 | E19: =D19-B14 -> 0.337
A20: Campbellfield | B20: 0.508 | D20: =SUM(B20:C20) -> 0.508 | E20: =D20-B14 -> 0.508
A21: Docklands | B21: 0.199 | D21: =SUM(B21:C21) -> 0.199 | E21: =D21-B14 -> 0.199
A22: Southbank | B22: 0.166 | D22: =SUM(B22:C22) -> 0.166 | E22: =D22-B14 -> 0.166
A23: Broadmeadows | B23: 0.451 | D23: =SUM(B23:C23) -> 0.451 | E23: =D23-B14 -> 0.451
A24: St Kilda | B24: 0.191 | D24: =SUM(B24:C24) -> 0.191 | E24: =D24-B14 -> 0.191
A25: Melton | B25: 0.444 | D25: =SUM(B25:C25) -> 0.444 | E25: =D25-B14 -> 0.444
A26: Werribe | B26: 0.318 | D26: =SUM(B26:C26) -> 0.318 | E26: =D26-B14 -> 0.318
A27: Morwell | B27: 0.449 | D27: =SUM(B27:C27) -> 0.449 | E27: =D27-B14 -> 0.449
A28: Civic | B28: 0.212 | D28: =SUM(B28:C28) -> 0.212 | E28: =D28-B14 -> 0.212
A29: Belconnen | B29: 0.219 | D29: =SUM(B29:C29) -> 0.219 | E29: =D29-B14 -> 0.219
A30: Kambah | B30: 0.335 | D30: =SUM(B30:C30) -> 0.335 | E30: =D30-B14 -> 0.335
A31: Phillip | B31: 0.159 | D31: =SUM(B31:C31) -> 0.159 | E31: =D31-B14 -> 0.159
A32: Gungahlin | B32: 0.202 | D32: =SUM(B32:C32) -> 0.202 | E32: =D32-B14 -> 0.202
A33: Braddon | B33: 0.142 | D33: =SUM(B33:C33) -> 0.142 | E33: =D33-B14 -> 0.142
A34: Ngunnawal | B34: 0.24 | D34: =SUM(B34:C34) -> 0.24 | E34: =D34-B14 -> 0.24
A35: Richardson | B35: 0.277 | D35: =SUM(B35:C35) -> 0.277 | E35: =D35-B14 -> 0.277
A36: Charnwood | B36: 0.297 | D36: =SUM(B36:C36) -> 0.297 | E36: =D36-B14 -> 0.297
A37: Narrabundah | B37: 0.3 | D37: =SUM(B37:C37) -> 0.3 | E37: =D37-B14 -> 0.3
A38: Adelaide CBD | B38: 0.336 | D38: =SUM(B38:C38) -> 0.336 | E38: =D38-B14 -> 0.336
A39: Sailsbury | B39: 0.446 | D39: =SUM(B39:C39) -> 0.446 | E39: =D39-B14 -> 0.446
A40: Elizabeth | B40: 0.469 | D40: =SUM(B40:C40) -> 0.469 | E40: =D40-B14 -> 0.469
A41: Daveron Park | B41: 0.467 | D41: =SUM(B41:C41) -> 0.467 | E41: =D41-B14 -> 0.467
A42: Oaklands Park | B42: 0.4 | D42: =SUM(B42:C42) -> 0.4 | E42: =D42-B14 -> 0.4
...

Sheet Poverty
A1: Suburb | B1: Percentage Below Low Income Line | C1: Households | D1: Households Below Low Income Line
A2: Blacktown | B2: 0.125
A3: CBD | B3: =D3/C3 -> 0.1702815 | C3: 4334 | D3: 738
A4: Penrith | B4: 0.135
A5: Mount Druitt | B5: 0.166
A6: Campbelltown | B6: =D6/C6 -> 0.19451055 | C6: 6303 | D6: 1226
A7: Liverpool | B7: 0.151
A8: Paramatta | B8: 0.131
A9: St Marys | B9: =D9/C9 -> 0.18235171 | C9: 4771 | D9: 870
A10: Surry Hills | B10: =D10/C10 -> 0.13760288 | C10: 7776 | D10: 1070
A13: Low Income Household: | B13: Median Weekly Income below gross value of $650 per week per household
A15: Melbourne CBD | B15: 0.18 | C15: 12400
A16: Yarra | B16: 0.132 | C16: 40646
A17: Carlton | B17: 0.297 | C17: 10344
A18: Frankston | B18: 0.22 | C18: 17419
A19: Campbellfield | B19: 0.248 | C19: 1594
A20: Docklands | B20: 0.139 | C20: 7540
A21: Southbank | B21: 0.119 | C21: 17463
A22: Broadmeadows | B22: 0.255 | C22: 3789
A23: St Kilda | B23: 0.141 | C23: 14096
A24: Melton | B24: 0.266 | C24: 3024
A25: Werribe | B25: 0.161 | C25: 17614
A26: Morwell | B26: 0.323 | C26: 7032
A27: Civic | B27: 0.119
A28: Belconnen | B28: 0.105
A29: Kambah | B29: 0.1
A30: Phillip | B30: 0.076
A31: Gungahlin | B31: 0.091
A32: Braddon | B32: 0.119
A33: Ngunnawal | B33: 0.09
A34: Richardson | B34: 0.101
A35: Charnwood | B35: 0.12
A36: Narrabundah | B36: 0.075
A37: Adelaide CBD | B37: 0.275
A38: Sailsbury | B38: 0.23
... A86: Nightcliff | B86: 0.15

Sheet Sources
A1: Suburb
A2: Blacktown | B2: https://abs.gov.au/census/find-census-data/quickstats/2021/LGA10750
A3: CBD | B3: https://abs.gov.au/census/find-census-data/quickstats/2021/117
A4: Penrith | B4: https://abs.gov.au/census/find-census-data/quickstats/2021/LGA16350
A5: Mount Druitt | B5: https://abs.gov.au/census/find-census-data/quickstats/2021/SAL12767
A6: Campbelltown | B6: https://www.abs.gov.au/census/find-census-data/quickstats/2021/LGA11500
A7: Liverpool | B7: https://abs.gov.au/census/find-census-data/quickstats/2021/LGA14900
A8: Paramatta | B8: https://www.abs.gov.au/census/find-census-data/quickstats/2021/LGA16260
A9: St Marys | B9: https://abs.gov.au/census/find-census-data/quickstats/2021/SAL13658
A10: Surry Hills | B10: https://abs.gov.au/census/find-census-data/quickstats/2021/SAL13714
A12: Overall Crime Stats | B12: https://chatgpt.com/c/690d7409-b5f0-8323-ad05-481eececa02a | C12: https://www.crimestatistics.vic.gov.au/crime-statistics/latest-crime-data-by-area
A13: Alcohol Consumption | B13: https://www.google.com/search?q=risky+alcohol+consumption+southbank+victoria&sca_esv=72372a46cdac1766&rlz=1C1ONGR_enAU1027AU1027&sxsrf=ANbL-n5QfhjHEKzfKJpnnvWZYkQckt-r9w%3A1771040641702&udm=50&fbs=ADc_l-aN0CWEZBOHjofHoaMMDiKpaEWjvZ2Py1XXV8d8KvlI3p-ML-906rRL_m6h4jR-tdAeyw6pOVABma0FfM0NmtARdcuGnZVoiSrEQCt2b10nLpXfp_br5K9gAh-TQhLPkaHBtLmn0tz30EfEzwQQNIGBo7V5X8o_GSLLrPozKSwR65BedD1rccPZR5nEKAbQKlfKLtThFU0GV4KIdILZXC12o41Lmg&aep=1&ntc=1&sa=X&ved=2ahUKEwjA_NLCiNiSAxXFr1YBHRI5IZ4Q2J8OegQIEBAE&biw=1280&bih=631&dpr=1.5&mstk=AUtExfDpjfNz1hZY3dfnoXZUMRjZcocpybBs1EM6hLKg67syvLvuyLjAOaTa3hI3Kp_w1TNnB-KdeBzqFJTonlzcoZEG8LB4dSetx3qFH7t26IUTuAfMdZ8yuSg8qhL44fYGe1GHhDixcyPKKUknnA40CIffFPZeRmJ57e2ozdhoibYOkAjIsbcM3oBLLrY2cxXyAS8qcSTr51rVDl1-_UcAFTU2yORJq7MS9h-NuxS0nAQrClQJPZFUxrfPXh4xYQ8GeF2qxKjT5AJxNKQlVBpyC8HuiLNDBgU0QtnHFGUtDAo8z10xI0XmNYdvbTXhn7c4vu6iaWWy8UbR_g&csuir=1&mtid=he-PacGmOouE4-EPl6SBsQ4
A14: Poverty | B14: https://www.abs.gov.au/census/find-census-data/quickstats/2021/116?utm_source=chatgpt.com
A15: Non-Sydney Suburb ABS Data | B15: https://www.abs.gov.au/census/find-census-data/search-by-area
